<?xml version="1.0" ?>
<!-- =================================================================================== -->
<!-- |    This document was autogenerated by xacro from robot.xacro                    | -->
<!-- |    EDITING THIS FILE BY HAND IS NOT RECOMMENDED                                 | -->
<!-- =================================================================================== -->
<robot name="go1_description">
  <material name="black">
    <color rgba="0.0 0.0 0.0 1.0"/>
  </material>
  <material name="blue">
    <color rgba="0.0 0.0 0.8 1.0"/>
  </material>
  <material name="green">
    <color rgba="0.0 0.8 0.0 1.0"/>
  </material>
  <material name="grey">
    <color rgba="0.2 0.2 0.2 1.0"/>
  </material>
  <material name="silver">
    <color rgba="0.9137254901960784 0.9137254901960784 0.8470588235294118 1.0"/>
  </material>
  <material name="orange">
    <color rgba="1.0 0.4235294117647059 0.0392156862745098 1.0"/>
  </material>
  <material name="brown">
    <color rgba="0.8705882352941177 0.8117647058823529 0.7647058823529411 1.0"/>
  </material>
  <material name="red">
    <color rgba="0.8 0.0 0.0 1.0"/>
  </material>
  <material name="white">
    <color rgba="1.0 1.0 1.0 1.0"/>
  </material>

  
  <gazebo reference="base">
    <material>Gazebo/Green</material>
    <turnGravityOff>false</turnGravityOff>
  </gazebo>
  <gazebo reference="trunk">
    <mu1>0.2</mu1>
    <mu2>0.2</mu2>
    <kp value="1000000.0"/>
    <kd value="1.0"/>
  </gazebo>
  <gazebo reference="stick_link">
    <mu1>0.2</mu1>
    <mu2>0.2</mu2>
    <material>Gazebo/White</material>
  </gazebo>
  <gazebo reference="imu_link">
    <mu1>0.2</mu1>
    <mu2>0.2</mu2>
    <material>Gazebo/Red</material>
  </gazebo>
  <!-- FL leg -->
  <gazebo reference="FL_hip">
    <mu1>0.2</mu1>
    <mu2>0.2</mu2>
    <material>Gazebo/DarkGrey</material>
  </gazebo>
  <gazebo reference="FL_thigh">
    <mu1>0.2</mu1>
    <mu2>0.2</mu2>
    <self_collide>1</self_collide>
    <material>Gazebo/DarkGrey</material>
    <kp value="1000000.0"/>
    <kd value="1.0"/>
  </gazebo>
  <gazebo reference="FL_calf">
    <mu1>0.2</mu1>
    <mu2>0.2</mu2>
    <self_collide>1</self_collide>
  </gazebo>
  <gazebo reference="FL_foot">
    <mu1>0.6</mu1>
    <mu2>0.6</mu2>
    <self_collide>1</self_collide>
    <material>Gazebo/DarkGrey</material>
    <kp value="1000000.0"/>
    <kd value="1.0"/>
  </gazebo>
  <!-- FR leg -->
  <gazebo reference="FR_hip">
    <mu1>0.2</mu1>
    <mu2>0.2</mu2>
    <material>Gazebo/DarkGrey</material>
  </gazebo>
  <gazebo reference="FR_thigh">
    <mu1>0.2</mu1>
    <mu2>0.2</mu2>
    <self_collide>1</self_collide>
    <material>Gazebo/DarkGrey</material>
    <kp value="1000000.0"/>
    <kd value="1.0"/>
  </gazebo>
  <gazebo reference="FR_calf">
    <mu1>0.2</mu1>
    <mu2>0.2</mu2>
    <self_collide>1</self_collide>
  </gazebo>
  <gazebo reference="FR_foot">
    <mu1>0.6</mu1>
    <mu2>0.6</mu2>
    <self_collide>1</self_collide>
    <material>Gazebo/DarkGrey</material>
    <kp value="1000000.0"/>
    <kd value="1.0"/>
  </gazebo>
  <!-- RL leg -->
  <gazebo reference="RL_hip">
    <mu1>0.2</mu1>
    <mu2>0.2</mu2>
    <material>Gazebo/DarkGrey</material>
  </gazebo>
  <gazebo reference="RL_thigh">
    <mu1>0.2</mu1>
    <mu2>0.2</mu2>
    <self_collide>1</self_collide>
    <material>Gazebo/DarkGrey</material>
    <kp value="1000000.0"/>
    <kd value="1.0"/>
  </gazebo>
  <gazebo reference="RL_calf">
    <mu1>0.2</mu1>
    <mu2>0.2</mu2>
    <self_collide>1</self_collide>
  </gazebo>
  <gazebo reference="RL_foot">
    <mu1>0.6</mu1>
    <mu2>0.6</mu2>
    <self_collide>1</self_collide>
    <material>Gazebo/DarkGrey</material>
    <kp value="1000000.0"/>
    <kd value="1.0"/>
  </gazebo>
  <!-- RR leg -->
  <gazebo reference="RR_hip">
    <mu1>0.2</mu1>
    <mu2>0.2</mu2>
    <material>Gazebo/DarkGrey</material>
  </gazebo>
  <gazebo reference="RR_thigh">
    <mu1>0.2</mu1>
    <mu2>0.2</mu2>
    <self_collide>1</self_collide>
    <material>Gazebo/DarkGrey</material>
    <kp value="1000000.0"/>
    <kd value="1.0"/>
  </gazebo>
  <gazebo reference="RR_calf">
    <mu1>0.2</mu1>
    <mu2>0.2</mu2>
    <self_collide>1</self_collide>
  </gazebo>
  <gazebo reference="RR_foot">
    <mu1>0.6</mu1>
    <mu2>0.6</mu2>
    <self_collide>1</self_collide>
    <material>Gazebo/DarkGrey</material>
    <kp value="1000000.0"/>
    <kd value="1.0"/>
  </gazebo>

  <link name="base">
    <visual>
      <origin rpy="0 0 0" xyz="0 0 0"/>
      <geometry>
        <box size="0.001 0.001 0.001"/>
      </geometry>
    </visual>
  </link>
  <joint name="floating_base" type="fixed">
    <origin rpy="0 0 0" xyz="0 0 0"/>
    <parent link="base"/>
    <child link="trunk"/>
  </joint>
  <link name="trunk">
    <visual>
      <origin rpy="0 0 0" xyz="0 0 0"/>
      <geometry>
        <mesh filename="package://go1_description/meshes/trunk.dae" scale="1 1 1"/>
      </geometry>
      <!-- <material name="orange"/> -->
    </visual>
    <collision>
      <origin rpy="0 0 0" xyz="0 0 0"/>
      <geometry>
        <box size="0.3762 0.0935 0.114"/>
      </geometry>
    </collision>
    <inertial>
      <origin rpy="0 0 0" xyz="0.0223 0.002 -0.0005"/>
      <mass value="5.204"/>
      <inertia ixx="0.0168352186" ixy="0.0004636141" ixz="0.0002367952" iyy="0.0656071082" iyz="3.6671e-05" izz="0.0742720659"/>
    </inertial>
  </link>
  <joint name="imu_joint" type="fixed">
    <parent link="trunk"/>
    <child link="imu_link"/>
    <origin rpy="0 0 0" xyz="-0.01592 -0.06659 -0.00617"/>
  </joint>
  <link name="imu_link">
    <inertial>
      <mass value="0.001"/>
      <origin rpy="0 0 0" xyz="0 0 0"/>
      <inertia ixx="0.0001" ixy="0" ixz="0" iyy="0.0001" iyz="0" izz="0.0001"/>
    </inertial>
    <visual>
      <origin rpy="0 0 0" xyz="0 0 0"/>
      <geometry>
        <box size="0.001 0.001 0.001"/>
      </geometry>
      <!-- <material name="red"/> -->
    </visual>
    <collision>
      <origin rpy="0 0 0" xyz="0 0 0"/>
      <geometry>
        <box size=".001 .001 .001"/>
      </geometry>
    </collision>
  </link>
  <joint name="FR_hip_joint" type="revolute">
    <origin rpy="0 0 0" xyz="0.1881 -0.04675 0"/>
    <parent link="trunk"/>
    <child link="FR_hip"/>
    <axis xyz="1 0 0"/>
    <dynamics damping="0.7" friction="0.2"/>
    <limit effort="23.7" lower="-1.0471975511965976" upper="1.0471975511965976" velocity="30.1"/>
  </joint>
  <link name="FR_hip">
    <visual>
      <origin rpy="3.141592653589793 0 0" xyz="0 0 0"/>
      <geometry>
        <mesh filename="package://go1_description/meshes/hip.dae" scale="1 1 1"/>
      </geometry>
      <!-- <material name="orange"/> -->
    </visual>
    <collision>
      <origin rpy="1.5707963267948966 0 0" xyz="0 0 0"/>
      <geometry>
        <cylinder length="0.04" radius="0.046"/>
      </geometry>
    </collision>
    <inertial>
      <origin rpy="0 0 0" xyz="-0.00541 0.00074 6e-06"/>
      <mass value="0.591"/>
      <inertia ixx="0.000374268192" ixy="-3.6844422e-05" ixz="-9.86754e-07" iyy="0.000635923669" iyz="1.172894e-06" izz="0.000457647394"/>
    </inertial>
  </link>
  <joint name="FR_hip_fixed" type="fixed">
    <origin rpy="0 0 0" xyz="0 -0.08 0"/>
    <parent link="FR_hip"/>
    <child link="FR_thigh_shoulder"/>
  </joint>
  <!-- this link is only for collision -->
  <link name="FR_thigh_shoulder">
    <collision>
      <origin rpy="1.5707963267948966 0 0" xyz="0 0 0"/>
      <geometry>
        <cylinder length="0.032" radius="0.041"/>
      </geometry>
    </collision>
  </link>
  <joint name="FR_thigh_joint" type="revolute">
    <origin rpy="0 0 0" xyz="0 -0.08 0"/>
    <parent link="FR_hip"/>
    <child link="FR_thigh"/>
    <axis xyz="0 1 0"/>
    <dynamics damping="0.7" friction="0.2"/>
    <limit effort="23.7" lower="-0.6632251157578452" upper="2.9670597283903604" velocity="30.1"/>
  </joint>
  <link name="FR_thigh">
    <visual>
      <origin rpy="0 0 0" xyz="0 0 0"/>
      <geometry>
        <mesh filename="package://go1_description/meshes/thigh_mirror.dae" scale="1 1 1"/>
      </geometry>
      <!-- <material name="orange"/> -->
    </visual>
    <collision>
      <origin rpy="0 1.5707963267948966 0" xyz="0 0 -0.1065"/>
      <geometry>
        <box size="0.213 0.0245 0.034"/>
      </geometry>
    </collision>
    <inertial>
      <origin rpy="0 0 0" xyz="-0.003468 0.018947 -0.032736"/>
      <mass value="0.92"/>
      <inertia ixx="0.005851561134" ixy="-1.783284e-06" ixz="0.000328291374" iyy="0.005596155105" iyz="-2.1430713e-05" izz="0.00107157026"/>
    </inertial>
  </link>
  <joint name="FR_calf_joint" type="revolute">
    <origin rpy="0 0 0" xyz="0 0 -0.213"/>
    <parent link="FR_thigh"/>
    <child link="FR_calf"/>
    <axis xyz="0 1 0"/>
    <dynamics damping="0.7" friction="0.2"/>
    <limit effort="23.7" lower="-2.722713633111154" upper="-0.8377580409572781" velocity="30.1"/>
  </joint>
  <link name="FR_calf">
    <visual>
      <origin rpy="0 0 0" xyz="0 0 0"/>
      <geometry>
        <mesh filename="package://go1_description/meshes/calf.dae" scale="1 1 1"/>
      </geometry>
      <!-- <material name="orange"/> -->
    </visual>
    <collision>
      <origin rpy="0 1.5707963267948966 0" xyz="0 0 -0.1065"/>
      <geometry>
        <box size="0.213 0.016 0.016"/>
      </geometry>
    </collision>
    <inertial>
      <origin rpy="0 0 0" xyz="0.006286 0.001307 -0.122269"/>
      <mass value="0.131"/>
      <inertia ixx="0.002939186297" ixy="1.440899e-06" ixz="-0.00010535955" iyy="0.00295576935" iyz="-2.4397752e-05" izz="3.0273372e-05"/>
    </inertial>
  </link>
  <joint name="FR_foot_fixed" type="fixed">
    <origin rpy="0 0 0" xyz="0 0 -0.213"/>
    <parent link="FR_calf"/>
    <child link="FR_foot"/>
  </joint>
  <link name="FR_foot">
    <visual>
      <origin rpy="0 0 0" xyz="0 0 0"/>
      <geometry>
        <sphere radius="0.01"/>
      </geometry>
      <!-- <material name="orange"/> -->
    </visual>
    <collision>
      <origin rpy="0 0 0" xyz="0 0 0"/>
      <geometry>
        <sphere radius="0.02"/>
      </geometry>
    </collision>
    <inertial>
      <mass value="0.06"/>
      <inertia ixx="9.600000000000001e-06" ixy="0.0" ixz="0.0" iyy="9.600000000000001e-06" iyz="0.0" izz="9.600000000000001e-06"/>
    </inertial>
  </link>

  <joint name="FL_hip_joint" type="revolute">
    <origin rpy="0 0 0" xyz="0.1881 0.04675 0"/>
    <parent link="trunk"/>
    <child link="FL_hip"/>
    <axis xyz="1 0 0"/>
    <dynamics damping="0.7" friction="0.2"/>
    <limit effort="23.7" lower="-1.0471975511965976" upper="1.0471975511965976" velocity="30.1"/>
  </joint>
  <link name="FL_hip">
    <visual>
      <origin rpy="0 0 0" xyz="0 0 0"/>
      <geometry>
        <mesh filename="package://go1_description/meshes/hip.dae" scale="1 1 1"/>
      </geometry>
      <!-- <material name="orange"/> -->
    </visual>
    <collision>
      <origin rpy="1.5707963267948966 0 0" xyz="0 0 0"/>
      <geometry>
        <cylinder length="0.04" radius="0.046"/>
      </geometry>
    </collision>
    <inertial>
      <origin rpy="0 0 0" xyz="-0.00541 -0.00074 6e-06"/>
      <mass value="0.591"/>
      <inertia ixx="0.000374268192" ixy="3.6844422e-05" ixz="-9.86754e-07" iyy="0.000635923669" iyz="-1.172894e-06" izz="0.000457647394"/>
    </inertial>
  </link>
  <joint name="FL_hip_fixed" type="fixed">
    <origin rpy="0 0 0" xyz="0 0.08 0"/>
    <parent link="FL_hip"/>
    <child link="FL_thigh_shoulder"/>
  </joint>
  <!-- this link is only for collision -->
  <link name="FL_thigh_shoulder">
    <collision>
      <origin rpy="1.5707963267948966 0 0" xyz="0 0 0"/>
      <geometry>
        <cylinder length="0.032" radius="0.041"/>
      </geometry>
    </collision>
  </link>
  <joint name="FL_thigh_joint" type="revolute">
    <origin rpy="0 0 0" xyz="0 0.08 0"/>
    <parent link="FL_hip"/>
    <child link="FL_thigh"/>
    <axis xyz="0 1 0"/>
    <dynamics damping="0.7" friction="0.2"/>
    <limit effort="23.7" lower="-0.6632251157578452" upper="2.9670597283903604" velocity="30.1"/>
  </joint>
  <link name="FL_thigh">
    <visual>
      <origin rpy="0 0 0" xyz="0 0 0"/>
      <geometry>
        <mesh filename="package://go1_description/meshes/thigh.dae" scale="1 1 1"/>
      </geometry>
      <!-- <material name="orange"/> -->
    </visual>
    <collision>
      <origin rpy="0 1.5707963267948966 0" xyz="0 0 -0.1065"/>
      <geometry>
        <box size="0.213 0.0245 0.034"/>
      </geometry>
    </collision>
    <inertial>
      <origin rpy="0 0 0" xyz="-0.003468 -0.018947 -0.032736"/>
      <mass value="0.92"/>
      <inertia ixx="0.005851561134" ixy="1.783284e-06" ixz="0.000328291374" iyy="0.005596155105" iyz="2.1430713e-05" izz="0.00107157026"/>
    </inertial>
  </link>
  <joint name="FL_calf_joint" type="revolute">
    <origin rpy="0 0 0" xyz="0 0 -0.213"/>
    <parent link="FL_thigh"/>
    <child link="FL_calf"/>
    <axis xyz="0 1 0"/>
    <dynamics damping="0.7" friction="0.2"/>
    <limit effort="23.7" lower="-2.722713633111154" upper="-0.8377580409572781" velocity="30.1"/>
  </joint>
  <link name="FL_calf">
    <visual>
      <origin rpy="0 0 0" xyz="0 0 0"/>
      <geometry>
        <mesh filename="package://go1_description/meshes/calf.dae" scale="1 1 1"/>
      </geometry>
      <!-- <material name="orange"/> -->
    </visual>
    <collision>
      <origin rpy="0 1.5707963267948966 0" xyz="0 0 -0.1065"/>
      <geometry>
        <box size="0.213 0.016 0.016"/>
      </geometry>
    </collision>
    <inertial>
      <origin rpy="0 0 0" xyz="0.006286 0.001307 -0.122269"/>
      <mass value="0.131"/>
      <inertia ixx="0.002939186297" ixy="1.440899e-06" ixz="-0.00010535955" iyy="0.00295576935" iyz="-2.4397752e-05" izz="3.0273372e-05"/>
    </inertial>
  </link>
  <joint name="FL_foot_fixed" type="fixed">
    <origin rpy="0 0 0" xyz="0 0 -0.213"/>
    <parent link="FL_calf"/>
    <child link="FL_foot"/>
  </joint>
  <link name="FL_foot">
    <visual>
      <origin rpy="0 0 0" xyz="0 0 0"/>
      <geometry>
        <sphere radius="0.01"/>
      </geometry>
      <!-- <material name="orange"/> -->
    </visual>
    <collision>
      <origin rpy="0 0 0" xyz="0 0 0"/>
      <geometry>
        <sphere radius="0.02"/>
      </geometry>
    </collision>
    <inertial>
      <mass value="0.06"/>
      <inertia ixx="9.600000000000001e-06" ixy="0.0" ixz="0.0" iyy="9.600000000000001e-06" iyz="0.0" izz="9.600000000000001e-06"/>
    </inertial>
  </link>

  <joint name="RR_hip_joint" type="revolute">
    <origin rpy="0 0 0" xyz="-0.1881 -0.04675 0"/>
    <parent link="trunk"/>
    <child link="RR_hip"/>
    <axis xyz="1 0 0"/>
    <dynamics damping="0.7" friction="0.2"/>
    <limit effort="23.7" lower="-1.0471975511965976" upper="1.0471975511965976" velocity="30.1"/>
  </joint>
  <link name="RR_hip">
    <visual>
      <origin rpy="3.141592653589793 3.141592653589793 0" xyz="0 0 0"/>
      <geometry>
        <mesh filename="package://go1_description/meshes/hip.dae" scale="1 1 1"/>
      </geometry>
      <!-- <material name="orange"/> -->
    </visual>
    <collision>
      <origin rpy="1.5707963267948966 0 0" xyz="0 0 0"/>
      <geometry>
        <cylinder length="0.04" radius="0.046"/>
      </geometry>
    </collision>
    <inertial>
      <origin rpy="0 0 0" xyz="0.00541 0.00074 6e-06"/>
      <mass value="0.591"/>
      <inertia ixx="0.000374268192" ixy="3.6844422e-05" ixz="9.86754e-07" iyy="0.000635923669" iyz="1.172894e-06" izz="0.000457647394"/>
    </inertial>
  </link>
  <joint name="RR_hip_fixed" type="fixed">
    <origin rpy="0 0 0" xyz="0 -0.08 0"/>
    <parent link="RR_hip"/>
    <child link="RR_thigh_shoulder"/>
  </joint>
  <!-- this link is only for collision -->
  <link name="RR_thigh_shoulder">
    <collision>
      <origin rpy="1.5707963267948966 0 0" xyz="0 0 0"/>
      <geometry>
        <cylinder length="0.032" radius="0.041"/>
      </geometry>
    </collision>
  </link>
  <joint name="RR_thigh_joint" type="revolute">
    <origin rpy="0 0 0" xyz="0 -0.08 0"/>
    <parent link="RR_hip"/>
    <child link="RR_thigh"/>
    <axis xyz="0 1 0"/>
    <dynamics damping="0.7" friction="0.2"/>
    <limit effort="23.7" lower="-0.6632251157578452" upper="2.9670597283903604" velocity="30.1"/>
  </joint>
  <link name="RR_thigh">
    <visual>
      <origin rpy="0 0 0" xyz="0 0 0"/>
      <geometry>
        <mesh filename="package://go1_description/meshes/thigh_mirror.dae" scale="1 1 1"/>
      </geometry>
      <!-- <material name="orange"/> -->
    </visual>
    <collision>
      <origin rpy="0 1.5707963267948966 0" xyz="0 0 -0.1065"/>
      <geometry>
        <box size="0.213 0.0245 0.034"/>
      </geometry>
    </collision>
    <inertial>
      <origin rpy="0 0 0" xyz="-0.003468 0.018947 -0.032736"/>
      <mass value="0.92"/>
      <inertia ixx="0.005851561134" ixy="-1.783284e-06" ixz="0.000328291374" iyy="0.005596155105" iyz="-2.1430713e-05" izz="0.00107157026"/>
    </inertial>
  </link>
  <joint name="RR_calf_joint" type="revolute">
    <origin rpy="0 0 0" xyz="0 0 -0.213"/>
    <parent link="RR_thigh"/>
    <child link="RR_calf"/>
    <axis xyz="0 1 0"/>
    <dynamics damping="0.7" friction="0.2"/>
    <limit effort="23.7" lower="-2.722713633111154" upper="-0.8377580409572781" velocity="30.1"/>
  </joint>
  <link name="RR_calf">
    <visual>
      <origin rpy="0 0 0" xyz="0 0 0"/>
      <geometry>
        <mesh filename="package://go1_description/meshes/calf.dae" scale="1 1 1"/>
      </geometry>
      <!-- <material name="orange"/> -->
    </visual>
    <collision>
      <origin rpy="0 1.5707963267948966 0" xyz="0 0 -0.1065"/>
      <geometry>
        <box size="0.213 0.016 0.016"/>
      </geometry>
    </collision>
    <inertial>
      <origin rpy="0 0 0" xyz="0.006286 0.001307 -0.122269"/>
      <mass value="0.131"/>
      <inertia ixx="0.002939186297" ixy="1.440899e-06" ixz="-0.00010535955" iyy="0.00295576935" iyz="-2.4397752e-05" izz="3.0273372e-05"/>
    </inertial>
  </link>
  <joint name="RR_foot_fixed" type="fixed">
    <origin rpy="0 0 0" xyz="0 0 -0.213"/>
    <parent link="RR_calf"/>
    <child link="RR_foot"/>
  </joint>
  <link name="RR_foot">
    <visual>
      <origin rpy="0 0 0" xyz="0 0 0"/>
      <geometry>
        <sphere radius="0.01"/>
      </geometry>
      <!-- <material name="orange"/> -->
    </visual>
    <collision>
      <origin rpy="0 0 0" xyz="0 0 0"/>
      <geometry>
        <sphere radius="0.02"/>
      </geometry>
    </collision>
    <inertial>
      <mass value="0.06"/>
      <inertia ixx="9.600000000000001e-06" ixy="0.0" ixz="0.0" iyy="9.600000000000001e-06" iyz="0.0" izz="9.600000000000001e-06"/>
    </inertial>
  </link>

  <joint name="RL_hip_joint" type="revolute">
    <origin rpy="0 0 0" xyz="-0.1881 0.04675 0"/>
    <parent link="trunk"/>
    <child link="RL_hip"/>
    <axis xyz="1 0 0"/>
    <dynamics damping="0.7" friction="0.2"/>
    <limit effort="23.7" lower="-1.0471975511965976" upper="1.0471975511965976" velocity="30.1"/>
  </joint>
  <link name="RL_hip">
    <visual>
      <origin rpy="0 3.141592653589793 0" xyz="0 0 0"/>
      <geometry>
        <mesh filename="package://go1_description/meshes/hip.dae" scale="1 1 1"/>
      </geometry>
      <!-- <material name="orange"/> -->
    </visual>
    <collision>
      <origin rpy="1.5707963267948966 0 0" xyz="0 0 0"/>
      <geometry>
        <cylinder length="0.04" radius="0.046"/>
      </geometry>
    </collision>
    <inertial>
      <origin rpy="0 0 0" xyz="0.00541 -0.00074 6e-06"/>
      <mass value="0.591"/>
      <inertia ixx="0.000374268192" ixy="-3.6844422e-05" ixz="9.86754e-07" iyy="0.000635923669" iyz="-1.172894e-06" izz="0.000457647394"/>
    </inertial>
  </link>
  <joint name="RL_hip_fixed" type="fixed">
    <origin rpy="0 0 0" xyz="0 0.08 0"/>
    <parent link="RL_hip"/>
    <child link="RL_thigh_shoulder"/>
  </joint>
  <!-- this link is only for collision -->
  <link name="RL_thigh_shoulder">
    <collision>
      <origin rpy="1.5707963267948966 0 0" xyz="0 0 0"/>
      <geometry>
        <cylinder length="0.032" radius="0.041"/>
      </geometry>
    </collision>
  </link>
  <joint name="RL_thigh_joint" type="revolute">
    <origin rpy="0 0 0" xyz="0 0.08 0"/>
    <parent link="RL_hip"/>
    <child link="RL_thigh"/>
    <axis xyz="0 1 0"/>
    <dynamics damping="0.7" friction="0.2"/>
    <limit effort="23.7" lower="-0.6632251157578452" upper="2.9670597283903604" velocity="30.1"/>
  </joint>
  <link name="RL_thigh">
    <visual>
      <origin rpy="0 0 0" xyz="0 0 0"/>
      <geometry>
        <mesh filename="package://go1_description/meshes/thigh.dae" scale="1 1 1"/>
      </geometry>
      <!-- <material name="orange"/> -->
    </visual>
    <collision>
      <origin rpy="0 1.5707963267948966 0" xyz="0 0 -0.1065"/>
      <geometry>
        <box size="0.213 0.0245 0.034"/>
      </geometry>
    </collision>
    <inertial>
      <origin rpy="0 0 0" xyz="-0.003468 -0.018947 -0.032736"/>
      <mass value="0.92"/>
      <inertia ixx="0.005851561134" ixy="1.783284e-06" ixz="0.000328291374" iyy="0.005596155105" iyz="2.1430713e-05" izz="0.00107157026"/>
    </inertial>
  </link>
  <joint name="RL_calf_joint" type="revolute">
    <origin rpy="0 0 0" xyz="0 0 -0.213"/>
    <parent link="RL_thigh"/>
    <child link="RL_calf"/>
    <axis xyz="0 1 0"/>
    <dynamics damping="0.7" friction="0.2"/>
    <limit effort="23.7" lower="-2.722713633111154" upper="-0.8377580409572781" velocity="30.1"/>
  </joint>
  <link name="RL_calf">
    <visual>
      <origin rpy="0 0 0" xyz="0 0 0"/>
      <geometry>
        <mesh filename="package://go1_description/meshes/calf.dae" scale="1 1 1"/>
      </geometry>
      <!-- <material name="orange"/> -->
    </visual>
    <collision>
      <origin rpy="0 1.5707963267948966 0" xyz="0 0 -0.1065"/>
      <geometry>
        <box size="0.213 0.016 0.016"/>
      </geometry>
    </collision>
    <inertial>
      <origin rpy="0 0 0" xyz="0.006286 0.001307 -0.122269"/>
      <mass value="0.131"/>
      <inertia ixx="0.002939186297" ixy="1.440899e-06" ixz="-0.00010535955" iyy="0.00295576935" iyz="-2.4397752e-05" izz="3.0273372e-05"/>
    </inertial>
  </link>
  <joint name="RL_foot_fixed" type="fixed">
    <origin rpy="0 0 0" xyz="0 0 -0.213"/>
    <parent link="RL_calf"/>
    <child link="RL_foot"/>
  </joint>
  <link name="RL_foot">
    <visual>
      <origin rpy="0 0 0" xyz="0 0 0"/>
      <geometry>
        <sphere radius="0.01"/>
      </geometry>
      <!-- <material name="orange"/> -->
    </visual>
    <collision>
      <origin rpy="0 0 0" xyz="0 0 0"/>
      <geometry>
        <sphere radius="0.02"/>
      </geometry>
    </collision>
    <inertial>
      <mass value="0.06"/>
      <inertia ixx="9.600000000000001e-06" ixy="0.0" ixz="0.0" iyy="9.600000000000001e-06" iyz="0.0" izz="9.600000000000001e-06"/>
    </inertial>
  </link>

  <joint name="camera_joint_face" type="fixed">
    <origin rpy="3.141592653589793 0 0" xyz="0.2785 0.0125 0.0167"/>
    <parent link="trunk"/>
    <child link="camera_face"/>
  </joint>
  <link name="camera_face">
    <collision>
      <origin rpy="0 0 0" xyz="0 0 0"/>
      <geometry>
        <box size=".001 .001 .001"/>
      </geometry>
    </collision>
    <visual>
      <origin rpy="0 0 0" xyz="0 0 0"/>
      <geometry>
        <mesh filename="package://go1_description/meshes/depthCamera.dae" scale="1 1 1"/>
      </geometry>
    </visual>
    <inertial>
      <mass value="1e-5"/>
      <origin rpy="0 0 0" xyz="0 0 0"/>
      <inertia ixx="1e-6" ixy="0" ixz="0" iyy="1e-6" iyz="0" izz="1e-6"/>
    </inertial>
  </link>
  <joint name="camera_optical_joint_face" type="fixed">
    <origin rpy="-1.5707963267948966 0 -1.5707963267948966" xyz="0 0 0"/>
    <parent link="camera_face"/>
    <child link="camera_optical_face"/>
  </joint>
  <link name="camera_optical_face">
        </link>

  <joint name="camera_joint_chin" type="fixed">
    <origin rpy="3.141592653589793 1.5707963267948966 0" xyz="0.2522 0.0125 -0.0436"/>
    <parent link="trunk"/>
    <child link="camera_chin"/>
  </joint>
  <link name="camera_chin">
    <collision>
      <origin rpy="0 0 0" xyz="0 0 0"/>
      <geometry>
        <box size=".001 .001 .001"/>
      </geometry>
    </collision>
    <visual>
      <origin rpy="0 0 0" xyz="0 0 0"/>
      <geometry>
        <mesh filename="package://go1_description/meshes/depthCamera.dae" scale="1 1 1"/>
      </geometry>
    </visual>
    <inertial>
      <mass value="1e-5"/>
      <origin rpy="0 0 0" xyz="0 0 0"/>
      <inertia ixx="1e-6" ixy="0" ixz="0" iyy="1e-6" iyz="0" izz="1e-6"/>
    </inertial>
  </link>
  <joint name="camera_optical_joint_chin" type="fixed">
    <origin rpy="-1.5707963267948966 0 -1.5707963267948966" xyz="0 0 0"/>
    <parent link="camera_chin"/>
    <child link="camera_optical_chin"/>
  </joint>
  <link name="camera_optical_chin">
        </link>

  <joint name="camera_joint_left" type="fixed">
    <origin rpy="3.141592653589793 0.2618 1.5707963267948966" xyz="-0.066 0.082 -0.0176"/>
    <parent link="trunk"/>
    <child link="camera_left"/>
  </joint>
  <link name="camera_left">
    <collision>
      <origin rpy="0 0 0" xyz="0 0 0"/>
      <geometry>
        <box size=".001 .001 .001"/>
      </geometry>
    </collision>
    <visual>
      <origin rpy="0 0 0" xyz="0 0 0"/>
      <geometry>
        <mesh filename="package://go1_description/meshes/depthCamera.dae" scale="1 1 1"/>
      </geometry>
    </visual>
    <inertial>
      <mass value="1e-5"/>
      <origin rpy="0 0 0" xyz="0 0 0"/>
      <inertia ixx="1e-6" ixy="0" ixz="0" iyy="1e-6" iyz="0" izz="1e-6"/>
    </inertial>
  </link>
  <joint name="camera_optical_joint_left" type="fixed">
    <origin rpy="-1.5707963267948966 0 -1.5707963267948966" xyz="0 0 0"/>
    <parent link="camera_left"/>
    <child link="camera_optical_left"/>
  </joint>
  <link name="camera_optical_left">
        </link>

  <joint name="camera_joint_right" type="fixed">
    <origin rpy="3.141592653589793 0.2618 -1.5707963267948966" xyz="-0.041 -0.082 -0.0176"/>
    <parent link="trunk"/>
    <child link="camera_right"/>
  </joint>
  <link name="camera_right">
    <collision>
      <origin rpy="0 0 0" xyz="0 0 0"/>
      <geometry>
        <box size=".001 .001 .001"/>
      </geometry>
    </collision>
    <visual>
      <origin rpy="0 0 0" xyz="0 0 0"/>
      <geometry>
        <mesh filename="package://go1_description/meshes/depthCamera.dae" scale="1 1 1"/>
      </geometry>
    </visual>
    <inertial>
      <mass value="1e-5"/>
      <origin rpy="0 0 0" xyz="0 0 0"/>
      <inertia ixx="1e-6" ixy="0" ixz="0" iyy="1e-6" iyz="0" izz="1e-6"/>
    </inertial>
  </link>
  <joint name="camera_optical_joint_right" type="fixed">
    <origin rpy="-1.5707963267948966 0 -1.5707963267948966" xyz="0 0 0"/>
    <parent link="camera_right"/>
    <child link="camera_optical_right"/>
  </joint>
  <link name="camera_optical_right">
        </link>

  <joint name="camera_joint_rearDown" type="fixed">
    <origin rpy="3.141592653589793 1.5707963267948966 0" xyz="-0.0825 0.0125 -0.04365"/>
    <parent link="trunk"/>
    <child link="camera_rearDown"/>
  </joint>
  <link name="camera_rearDown">
    <collision>
      <origin rpy="0 0 0" xyz="0 0 0"/>
      <geometry>
        <box size=".001 .001 .001"/>
      </geometry>
    </collision>
    <visual>
      <origin rpy="0 0 0" xyz="0 0 0"/>
      <geometry>
        <mesh filename="package://go1_description/meshes/depthCamera.dae" scale="1 1 1"/>
      </geometry>
    </visual>
    <inertial>
      <mass value="1e-5"/>
      <origin rpy="0 0 0" xyz="0 0 0"/>
      <inertia ixx="1e-6" ixy="0" ixz="0" iyy="1e-6" iyz="0" izz="1e-6"/>
    </inertial>
  </link>
  <joint name="camera_optical_joint_rearDown" type="fixed">
    <origin rpy="-1.5707963267948966 0 -1.5707963267948966" xyz="0 0 0"/>
    <parent link="camera_rearDown"/>
    <child link="camera_optical_rearDown"/>
  </joint>
  <link name="camera_optical_rearDown">
        </link>

  <joint name="camera_laserscan_joint_left" type="fixed">
    <origin rpy="0 0.2618 0" xyz="0 0 0"/>
    <parent link="camera_left"/>
    <child link="camera_laserscan_link_left"/>
  </joint>
  <link name="camera_laserscan_link_left">
    </link>
  <joint name="camera_laserscan_joint_right" type="fixed">
    <origin rpy="0 0.2618 0" xyz="0 0 0"/>
    <parent link="camera_right"/>
    <child link="camera_laserscan_link_right"/>
  </joint>
  <link name="camera_laserscan_link_right">
    </link>
  <joint name="ultraSound_joint_left" type="fixed">
    <origin rpy="0 0.2618 1.5707963267948966" xyz="-0.0535  0.0826 0.00868"/>
    <parent link="trunk"/>
    <child link="ultraSound_left"/>
  </joint>
  <link name="ultraSound_left">
    <collision>
      <origin rpy="0 0 0" xyz="0 0 0"/>
      <geometry>
        <box size=".001 .001 .001"/>
      </geometry>
    </collision>
    <visual>
      <origin rpy="0 0 0" xyz="0 0 0"/>
      <geometry>
        <mesh filename="package://go1_description/meshes/ultraSound.dae" scale="1 1 1"/>
      </geometry>
      <material name="black"/>
    </visual>
    <inertial>
      <mass value="1e-5"/>
      <origin rpy="0 0 0" xyz="0 0 0"/>
      <inertia ixx="1e-6" ixy="0" ixz="0" iyy="1e-6" iyz="0" izz="1e-6"/>
    </inertial>
  </link>
  <joint name="ultraSound_joint_right" type="fixed">
    <origin rpy="0 0.2618 -1.5707963267948966" xyz="-0.0535 -0.0826 0.00868"/>
    <parent link="trunk"/>
    <child link="ultraSound_right"/>
  </joint>
  <link name="ultraSound_right">
    <collision>
      <origin rpy="0 0 0" xyz="0 0 0"/>
      <geometry>
        <box size=".001 .001 .001"/>
      </geometry>
    </collision>
    <visual>
      <origin rpy="0 0 0" xyz="0 0 0"/>
      <geometry>
        <mesh filename="package://go1_description/meshes/ultraSound.dae" scale="1 1 1"/>
      </geometry>
      <material name="black"/>
    </visual>
    <inertial>
      <mass value="1e-5"/>
      <origin rpy="0 0 0" xyz="0 0 0"/>
      <inertia ixx="1e-6" ixy="0" ixz="0" iyy="1e-6" iyz="0" izz="1e-6"/>
    </inertial>
  </link>
  <joint name="ultraSound_joint_face" type="fixed">
    <origin rpy="0 0 0" xyz="0.2747 0.0 -0.0088"/>
    <parent link="trunk"/>
    <child link="ultraSound_face"/>
  </joint>
  <link name="ultraSound_face">
    <collision>
      <origin rpy="0 0 0" xyz="0 0 0"/>
      <geometry>
        <box size=".001 .001 .001"/>
      </geometry>
    </collision>
    <visual>
      <origin rpy="0 0 0" xyz="0 0 0"/>
      <geometry>
        <mesh filename="package://go1_description/meshes/ultraSound.dae" scale="1 1 1"/>
      </geometry>
      <material name="black"/>
    </visual>
    <inertial>
      <mass value="1e-5"/>
      <origin rpy="0 0 0" xyz="0 0 0"/>
      <inertia ixx="1e-6" ixy="0" ixz="0" iyy="1e-6" iyz="0" izz="1e-6"/>
    </inertial>
  </link>
  
  <ros2_control name="GazeboSystem" type="system">
  <hardware>
    <plugin>gazebo_ros2_control/GazeboSystem</plugin>
  </hardware>
  
  <joint name="FL_hip_joint">
    <command_interface name="position"/>

    <state_interface name="position"/>
    <state_interface name="velocity"/>
    <state_interface name="effort"/>
  </joint>
  <joint name="FL_thigh_joint">
    <command_interface name="position"/>

    <state_interface name="position"/>
    <state_interface name="velocity"/>
    <state_interface name="effort"/>
  </joint>
  <joint name="FL_calf_joint">
    <command_interface name="position"/>

    <state_interface name="position"/>
    <state_interface name="velocity"/>
    <state_interface name="effort"/>
  </joint>
  
  <joint name="FR_hip_joint">
    <command_interface name="position"/>

    <state_interface name="position"/>
    <state_interface name="velocity"/>
    <state_interface name="effort"/>
  </joint>
  <joint name="FR_thigh_joint">
    <command_interface name="position"/>

    <state_interface name="position"/>
    <state_interface name="velocity"/>
    <state_interface name="effort"/>
  </joint>
  <joint name="FR_calf_joint">
    <command_interface name="position"/>

    <state_interface name="position"/>
    <state_interface name="velocity"/>
    <state_interface name="effort"/>
  </joint>
  
  <joint name="RL_hip_joint">
    <command_interface name="position"/>

    <state_interface name="position"/>
    <state_interface name="velocity"/>
    <state_interface name="effort"/>
  </joint>
  <joint name="RL_thigh_joint">
    <command_interface name="position"/>

    <state_interface name="position"/>
    <state_interface name="velocity"/>
    <state_interface name="effort"/>
  </joint>
  <joint name="RL_calf_joint">
    <command_interface name="position"/>

    <state_interface name="position"/>
    <state_interface name="velocity"/>
    <state_interface name="effort"/>
  </joint>
  
  <joint name="RR_hip_joint">
    <command_interface name="position"/>

    <state_interface name="position"/>
    <state_interface name="velocity"/>
    <state_interface name="effort"/>
  </joint>
  <joint name="RR_thigh_joint">
    <command_interface name="position"/>

    <state_interface name="position"/>
    <state_interface name="velocity"/>
    <state_interface name="effort"/>
  </joint>
  <joint name="RR_calf_joint">
    <command_interface name="position"/>

    <state_interface name="position"/>
    <state_interface name="velocity"/>
    <state_interface name="effort"/>
  </joint>
</ros2_control>

<gazebo>
    <plugin filename="libgazebo_ros2_control.so" name="gazebo_ros2_control">
      <robot_param>robot_description</robot_param>
      <robot_param_node>robot_state_publisher</robot_param_node>
      <parameters>/home/ros/ros2_ws/src/go1_description/config/robot_control.yaml</parameters>
    </plugin>
</gazebo>
  
</robot>

